Workbook

Sheet Final
B1: uM | L1: AREA
A2: Filename | B2: cFMN | C2: FAD | D2: FMN | E2: AceCoA | F2: AMP | G2: NAD | H2: CoA | I2: ADP | J2: ATP | K2: SAM | L2: Panthothenic_acid_B5 | M2: NAM | N2: Rivoflavin_B2 | O2: NADH | P2: NADP | Q2: NADPH
A3: 1 | B3: ='uM (final) '!#REF! -> #REF! | C3: ='uM (final) '!U3 -> 0.058751328 | D3: ='uM (final) '!#REF! -> #REF! | E3: ='uM (final) '!V3 -> 0.060636208 | F3: ='uM (final) '!#REF! -> #REF! | G3: ='uM (final) '!W3 -> 0.48718037 | H3: ='uM (final) '!X3 -> 0 | I3: ='uM (final) '!Y3 -> 0.61557964 | J3: ='uM (final) '!Z3 -> 3.7292259 | K3: ='uM (final) '!AA3 -> 0.1828412 | L3: 16659759 | M3: 636057.02 | N3: 0 | O3: 21191.292 | P3: 23755.616 | Q3: 0 | S3: Orange: Height blelow 1E4
A4: 2 | B4: ='uM (final) '!#REF! -> #REF! | C4: ='uM (final) '!U4 -> 0.058447733 | D4: ='uM (final) '!#REF! -> #REF! | E4: ='uM (final) '!V4 -> 0.060825236 | F4: ='uM (final) '!#REF! -> #REF! | G4: ='uM (final) '!W4 -> 0.46674623 | H4: ='uM (final) '!X4 -> 0 | I4: ='uM (final) '!Y4 -> 0.66103656 | J4: ='uM (final) '!Z4 -> 3.4219301 | K4: ='uM (final) '!AA4 -> 0.19068498 | L4: 17523720 | M4: 811243.28 | N4: 0 | O4: 61930.218 | P4: 22262.885 | Q4: 0 | S4: Green: not sure
A5: 3 | B5: ='uM (final) '!#REF! -> #REF! | C5: ='uM (final) '!U5 -> 0.059098165 | D5: ='uM (final) '!#REF! -> #REF! | E5: ='uM (final) '!V5 -> 0.061044727 | F5: ='uM (final) '!#REF! -> #REF! | G5: ='uM (final) '!W5 -> 0.50157591 | H5: ='uM (final) '!X5 -> 0 | I5: ='uM (final) '!Y5 -> 0.78752517 | J5: ='uM (final) '!Z5 -> 2.9654645 | K5: ='uM (final) '!AA5 -> 0.17973164 | L5: 19277570 | M5: 1004545.2 | N5: 4414.9022 | O5: 49737.387 | P5: 27383.156 | Q5: 996.56109
A6: 4 | B6: ='uM (final) '!#REF! -> #REF! | C6: ='uM (final) '!U6 -> 0.057516999 | D6: ='uM (final) '!#REF! -> #REF! | E6: ='uM (final) '!V6 -> 0.061710437 | F6: ='uM (final) '!#REF! -> #REF! | G6: ='uM (final) '!W6 -> 0.23023277 | H6: ='uM (final) '!X6 -> 0 | I6: ='uM (final) '!Y6 -> 0.96654071 | J6: ='uM (final) '!Z6 -> 2.0389322 | K6: ='uM (final) '!AA6 -> 0.17655404 | L6: 3598273.1 | M6: 206003.08 | N6: 0 | O6: 298466.3 | P6: 21601.385 | Q6: 23887.577
A7: 5 | B7: ='uM (final) '!#REF! -> #REF! | C7: ='uM (final) '!U7 -> 0.05807149 | D7: ='uM (final) '!#REF! -> #REF! | E7: ='uM (final) '!V7 -> 0.064868697 | F7: ='uM (final) '!#REF! -> #REF! | G7: ='uM (final) '!W7 -> 0.31818358 | H7: ='uM (final) '!X7 -> 0 | I7: ='uM (final) '!Y7 -> 1.2736239 | J7: ='uM (final) '!Z7 -> 2.6237022 | K7: ='uM (final) '!AA7 -> 0.21157078 | L7: 3776005.6 | M7: 270496.59 | N7: 0 | O7: 332746.77 | P7: 41957.672 | Q7: 37318.4
A8: 6 | B8: ='uM (final) '!#REF! -> #REF! | C8: ='uM (final) '!U8 -> 0.05702011 | D8: ='uM (final) '!#REF! -> #REF! | E8: ='uM (final) '!V8 -> 0.061671489 | F8: ='uM (final) '!#REF! -> #REF! | G8: ='uM (final) '!W8 -> 0.25161539 | H8: ='uM (final) '!X8 -> 0 | I8: ='uM (final) '!Y8 -> 1.0982071 | J8: ='uM (final) '!Z8 -> 1.7504292 | K8: ='uM (final) '!AA8 -> 0.2029127 | L8: 3316158.3 | M8: 242142.74 | N8: 0 | O8: 354257.62 | P8: 22038.204 | Q8: 63092.456
A9: 7 | B9: ='uM (final) '!#REF! -> #REF! | C9: ='uM (final) '!U9 -> 0.058867698 | D9: ='uM (final) '!#REF! -> #REF! | E9: ='uM (final) '!V9 -> 0.061499655 | F9: ='uM (final) '!#REF! -> #REF! | G9: ='uM (final) '!W9 -> 0.28718468 | H9: ='uM (final) '!X9 -> 0 | I9: ='uM (final) '!Y9 -> 0.45932808 | J9: ='uM (final) '!Z9 -> 4.1292896 | K9: ='uM (final) '!AA9 -> 0.22043841 | L9: 18287001 | M9: 217237.09 | N9: 0 | O9: 384514.18 | P9: 26231.475 | Q9: 64267.632
A10: 8 | B10: ='uM (final) '!#REF! -> #REF! | C10: ='uM (final) '!U10 -> 0.05921692 | D10: ='uM (final) '!#REF! -> #REF! | E10: ='uM (final) '!V10 -> 0.061742563 | F10: ='uM (final) '!#REF! -> #REF! | G10: ='uM (final) '!W10 -> 0.30003782 | H10: ='uM (final) '!X10 -> 0 | I10: ='uM (final) '!Y10 -> 0.48383551 | J10: ='uM (final) '!Z10 -> 4.1917909 | K10: ='uM (final) '!AA10 -> 0.21569567 | L10: 21173956 | M10: 463399.36 | N10: 0 | O10: 404488.48 | P10: 29220.541 | Q10: 73870.498
A11: 9 | B11: ='uM (final) '!#REF! -> #REF! | C11: ='uM (final) '!U11 -> 0.059043905 | D11: ='uM (final) '!#REF! -> #REF! | E11: ='uM (final) '!V11 -> 0.061438173 | F11: ='uM (final) '!#REF! -> #REF! | G11: ='uM (final) '!W11 -> 0.30868862 | H11: ='uM (final) '!X11 -> 0 | I11: ='uM (final) '!Y11 -> 0.50191972 | J11: ='uM (final) '!Z11 -> 4.5225305 | K11: ='uM (final) '!AA11 -> 0.2200015 | L11: 21001155 | M11: 234769.04 | N11: 2724.1156 | O11: 475996.19 | P11: 35690.199 | Q11: 76761.256
A12: 10 | B12: ='uM (final) '!#REF! -> #REF! | C12: ='uM (final) '!U12 -> 0.05861699 | D12: ='uM (final) '!#REF! -> #REF! | E12: ='uM (final) '!V12 -> 0.060496628 | F12: ='uM (final) '!#REF! -> #REF! | G12: ='uM (final) '!W12 -> 0.53661842 | H12: ='uM (final) '!X12 -> 0 | I12: ='uM (final) '!Y12 -> 0.48746546 | J12: ='uM (final) '!Z12 -> 3.7316753 | K12: ='uM (final) '!AA12 -> 0.2319749 | L12: 17325204 | M12: 2324404.2 | N12: 849349.89 | O12: 421272.28 | P12: 44360.138 | Q12: 77829.453
A13: 11 | B13: ='uM (final) '!#REF! -> #REF! | C13: ='uM (final) '!U13 -> 0.058592609 | D13: ='uM (final) '!#REF! -> #REF! | E13: ='uM (final) '!V13 -> 0.061290032 | F13: ='uM (final) '!#REF! -> #REF! | G13: ='uM (final) '!W13 -> 0.47831245 | H13: ='uM (final) '!X13 -> 0 | I13: ='uM (final) '!Y13 -> 0.43384934 | J13: ='uM (final) '!Z13 -> 3.4989121 | K13: ='uM (final) '!AA13 -> 0.21039834 | L13: 14609645 | M13: 1796839.6 | N13: 554884.18 | O13: 411788.01 | P13: 35585.018 | Q13: 35041.707
A14: 12 | B14: ='uM (final) '!#REF! -> #REF! | C14: ='uM (final) '!U14 -> 0.058478334 | D14: ='uM (final) '!#REF! -> #REF! | E14: ='uM (final) '!V14 -> 0.062429307 | F14: ='uM (final) '!#REF! -> #REF! | G14: ='uM (final) '!W14 -> 0.5421841 | H14: ='uM (final) '!X14 -> 0 | I14: ='uM (final) '!Y14 -> 0.46110291 | J14: ='uM (final) '!Z14 -> 3.6669632 | K14: ='uM (final) '!AA14 -> 0.22274872 | L14: 15307385 | M14: 4887364.1 | N14: 1172735.2 | O14: 521911.84 | P14: 35225.383 | Q14: 85725.867
A15: 13 | B15: ='uM (final) '!#REF! -> #REF! | C15: ='uM (final) '!U15 -> 0.06572692 | D15: ='uM (final) '!#REF! -> #REF! | E15: ='uM (final) '!V15 -> 0.071050476 | F15: ='uM (final) '!#REF! -> #REF! | G15: ='uM (final) '!W15 -> 1.4517582 | H15: ='uM (final) '!X15 -> 0.9311588 | I15: ='uM (final) '!Y15 -> 1.2967315 | J15: ='uM (final) '!Z15 -> 13.219033 | K15: ='uM (final) '!AA15 -> 0.41255341 | L15: 43410615 | M15: 9986497.9 | N15: 3829.1186 | O15: 2640435.8 | P15: 173492.8 | Q15: 271290.83
A16: 14 | B16: ='uM (final) '!#REF! -> #REF! | C16: ='uM (final) '!U16 -> 0.064452919 | D16: ='uM (final) '!#REF! -> #REF! | E16: ='uM (final) '!V16 -> 0.070643213 | F16: ='uM (final) '!#REF! -> #REF! | G16: ='uM (final) '!W16 -> 1.2524656 | H16: ='uM (final) '!X16 -> 0.94074132 | I16: ='uM (final) '!Y16 -> 1.1671313 | J16: ='uM (final) '!Z16 -> 10.871246 | K16: ='uM (final) '!AA16 -> 0.33484005 | L16: 31649421 | M16: 2822613.4 | N16: 0 | O16: 2435981 | P16: 126165.17 | Q16: 240176.91
A17: 15 | B17: ='uM (final) '!#REF! -> #REF! | C17: ='uM (final) '!U17 -> 0.066418387 | D17: ='uM (final) '!#REF! -> #REF! | E17: ='uM (final) '!V17 -> 0.075484569 | F17: ='uM (final) '!#REF! -> #REF! | G17: ='uM (final) '!W17 -> 1.5284962 | H17: ='uM (final) '!X17 -> 0.96501271 | I17: ='uM (final) '!Y17 -> 1.3399376 | J17: ='uM (final) '!Z17 -> 13.057106 | K17: ='uM (final) '!AA17 -> 0.37869883 | L17: 42177787 | M17: 3357727 | N17: 0 | O17: 2304910.5 | P17: 215242.4 | Q17: 259692.89
A18: 16 | B18: ='uM (final) '!#REF! -> #REF! | C18: ='uM (final) '!U18 -> 0.058157978 | D18: ='uM (final) '!#REF! -> #REF! | E18: ='uM (final) '!V18 -> 0.079158806 | F18: ='uM (final) '!#REF! -> #REF! | G18: ='uM (final) '!W18 -> 0.23128558 | H18: ='uM (final) '!X18 -> 0.92069001 | I18: ='uM (final) '!Y18 -> 3.1006128 | J18: ='uM (final) '!Z18 -> 3.7006379 | K18: ='uM (final) '!AA18 -> 0.42398647 | L18: 2895570.1 | M18: 301277.85 | N18: 0 | O18: 421251.72 | P18: 106350.71 | Q18: 112295.8
A19: 17 | B19: ='uM (final) '!#REF! -> #REF! | C19: ='uM (final) '!U19 -> 0.057143842 | D19: ='uM (final) '!#REF! -> #REF! | E19: ='uM (final) '!V19 -> 0.074806176 | F19: ='uM (final) '!#REF! -> #REF! | G19: ='uM (final) '!W19 -> 0.17608101 | H19: ='uM (final) '!X19 -> 0.92580542 | I19: ='uM (final) '!Y19 -> 2.7918425 | J19: ='uM (final) '!Z19 -> 4.3153543 | K19: ='uM (final) '!AA19 -> 0.3869351 | L19: 3041357 | M19: 149062.73 | N19: 0 | O19: 692702.72 | P19: 61379.669 | Q19: 116588.82
A20: 18 | B20: ='uM (final) '!#REF! -> #REF! | C20: ='uM (final) '!U20 -> 0.057384867 | D20: ='uM (final) '!#REF! -> #REF! | E20: ='uM (final) '!V20 -> 0.076940245 | F20: ='uM (final) '!#REF! -> #REF! | G20: ='uM (final) '!W20 -> 0.20616767 | H20: ='uM (final) '!X20 -> 0.92921995 | I20: ='uM (final) '!Y20 -> 3.1642615 | J20: ='uM (final) '!Z20 -> 6.2747502 | K20: ='uM (final) '!AA20 -> 0.43569943 | L20: 3019195.1 | M20: 287361.01 | N20: 0 | O20: 677165.44 | P20: 112318.5 | Q20: 104811.42
A21: 19 | B21: ='uM (final) '!#REF! -> #REF! | C21: ='uM (final) '!U21 -> 0.065998173 | D21: ='uM (final) '!#REF! -> #REF! | E21: ='uM (final) '!V21 -> 0.073531835 | F21: ='uM (final) '!#REF! -> #REF! | G21: ='uM (final) '!W21 -> 0.21409106 | H21: ='uM (final) '!X21 -> 0.95447629 | I21: ='uM (final) '!Y21 -> 0.90729895 | J21: ='uM (final) '!Z21 -> 12.867424 | K21: ='uM (final) '!AA21 -> 0.44107061 | L21: 41245443 | M21: 157163.17 | N21: 163361.46 | O21: 577412.25 | P21: 112352.82 | Q21: 115966.14
... A74: M24 | B74: ='uM (final) '!#REF! -> #REF! | C74: ='uM (final) '!U74 -> 0.057166311 | D74: ='uM (final) '!#REF! -> #REF! | E74: ='uM (final) '!V74 -> 0.056194925 | F74: ='uM (final) '!#REF! -> #REF! | G74: ='uM (final) '!W74 -> 0.021354066 | H74: ='uM (final) '!X74 -> 0.92069001 | I74: ='uM (final) '!Y74 -> 0.11368458 | J74: ='uM (final) '!Z74 -> 0.061732159 | K74: ='uM (final) '!AA74 -> 0.091238216 | L74: 72326192 | M74: 4.7036037e+08 | N74: 33646815 | O74: 0 | P74: 0 | Q74: 0

Sheet Area (final)
A1: AREA
A2: Filename | B2: Panthothenic_acid_B5 | C2: NAM | D2: Rivoflavin_B2 | E2: NADH | F2: SACH | G2: ADRR | H2: NADP | I2: NMN | J2: NADPH
A3: 1 | B3: 16659759 | C3: 636057.02 | D3: 0 | E3: 21191.292 | F3: 5797.1893 | G3: 111772.93 | H3: 23755.616 | I3: 0 | J3: 0
A4: 2 | B4: 17523720 | C4: 811243.28 | D4: 0 | E4: 61930.218 | F4: 38497.199 | G4: 97758.374 | H4: 22262.885 | I4: 0 | J4: 0
A5: 3 | B5: 19277570 | C5: 1004545.2 | D5: 4414.9022 | E5: 49737.387 | F5: 64495.365 | G5: 100310.81 | H5: 27383.156 | I5: 0 | J5: 996.56109
A6: 4 | B6: 3598273.1 | C6: 206003.08 | D6: 0 | E6: 298466.3 | F6: 6649.3735 | G6: 32193.447 | H6: 21601.385 | I6: 0 | J6: 23887.577
A7: 5 | B7: 3776005.6 | C7: 270496.59 | D7: 0 | E7: 332746.77 | F7: 43870.768 | G7: 46949.288 | H7: 41957.672 | I7: 0 | J7: 37318.4
A8: 6 | B8: 3316158.3 | C8: 242142.74 | D8: 0 | E8: 354257.62 | F8: 4072.8517 | G8: 43420.215 | H8: 22038.204 | I8: 0 | J8: 63092.456
A9: 7 | B9: 18287001 | C9: 217237.09 | D9: 0 | E9: 384514.18 | F9: 3357.2109 | G9: 38908.555 | H9: 26231.475 | I9: 0 | J9: 64267.632
A10: 8 | B10: 21173956 | C10: 463399.36 | D10: 0 | E10: 404488.48 | F10: 8620.4577 | G10: 42385.261 | H10: 29220.541 | I10: 0 | J10: 73870.498
A11: 9 | B11: 21001155 | C11: 234769.04 | D11: 2724.1156 | E11: 475996.19 | F11: 19475.259 | G11: 45065.537 | H11: 35690.199 | I11: 0 | J11: 76761.256
A12: 10 | B12: 17325204 | C12: 2324404.2 | D12: 849349.89 | E12: 421272.28 | F12: 4969.1902 | G12: 74879.587 | H12: 44360.138 | I12: 0 | J12: 77829.453
A13: 11 | B13: 14609645 | C13: 1796839.6 | D13: 554884.18 | E13: 411788.01 | F13: 6192.4536 | G13: 63870.664 | H13: 35585.018 | I13: 0 | J13: 35041.707
A14: 12 | B14: 15307385 | C14: 4887364.1 | D14: 1172735.2 | E14: 521911.84 | F14: 4057.3058 | G14: 100345.93 | H14: 35225.383 | I14: 0 | J14: 85725.867
... A74: M24 | B74: 72326192 | C74: 4.7036037e+08 | D74: 33646815 | E74: 0 | F74: 204879.44 | G74: 0 | H74: 0 | I74: 0 | J74: 0

Sheet uM (final) 
A1: AREA | S1: uM | AF1: nmol/mg | AR1: BCA | AZ1: area | BE1: area/mg protein
A2: Filename | C2: FAD | D2: AceCoA | E2: AMP | F2: NAD | G2: CoA | H2: ADP | I2: ATP | J2: SAM | K2: ADRR | N2: FAD | O2: NAD | P2: ATP | Q2: SAM | S2: Filename | U2: FAD | V2: AceCoA | W2: NAD | X2: CoA | Y2: ADP | Z2: ATP | AA2: SAM | AB2: ADRR | AD2: Filename | AE2: Column1 | AF2: FAD | AG2: AceCoA | AH2: NAD | AI2: CoA | AJ2: ADP | AK2: ATP | AL2: SAM | AM2: ADPR | AP2: Sample ID | AQ2: Mean Protein samples | AR2: Mean without lysis | AS2: Protein Concentration | AT2: Total protein mg | AU2: Avg total protein (mg) | AX2: Sample Name | AY2: Panthothenic_acid_B5 | AZ2: NAM_B3 | BA2: B2 Riboflavin | BC2: Sample Name | BD2: Panthothenic_acid_B5 | BE2: NAM_B3 | BF2: B2
A3: 1 | B3: Fully supplemented 24h | C3: 27735.752 | D3: 43432.029 | E3: 1363676.6 | F3: 5643378.4 | G3: 0 | H3: 2528184.1 | I3: 7049507.3 | J3: 1785793.2 | K3: 111772.93 | M3: Slope, a | N3: ='Calibration curve'!B11 -> 11091136 | O3: ='Calibration curve'!C11 -> 12114770 | P3: ='Calibration curve'!D11 -> 1922070.6 | Q3: ='Calibration curve'!E11 -> 19374853 | S3: 1 | T3: Fully supplemented 24h | U3: =(C3-$N$4)/$N$3 -> 0.058751328 | V3: =(D3-$O$12)/$O$11 -> 0.060636208 | W3: =(F3-$O$4)/$O$3 -> 0.48718037 | X3: 0 | Y3: =(H3-$P$8)/$P$7 -> 0.61557964 | Z3: =(I3-$P$4)/$P$3 -> 3.7292259 | AA3: =(J3-$Q$4)/$Q$3 -> 0.1828412 | AB3: =(K3-$N$19)/$N$18 -> 0.23808333 | AD3: 1 | AE3: Fully supplemented 24h | AF3: =(U3*0.0005*1000) /$AU$3 -> 0.33384651 | AG3: =(V3*0.0005*1000) /$AU3 -> 0.34455709 | AH3: =(W3*0.0005*1000) /$AU3 -> 2.7683368 | AI3: =(X3*0.0005*1000) /$AU3 -> 0 | AJ3: =(Y3*0.0005*1000) /$AU3 -> 3.4979484 | AK3: =(Z3*0.0005*1000) /$AU3 -> 21.190824 | AL3: =(AA3*0.0005*1000) /$AU3 -> 1.0389705 | AM3: =(AB3*0.0005*1000) /$AU3 -> 1.3528764 | AP3: 1 | AQ3: 0.36925 | AR3: 0.23655 | AS3: 0.37279662 | AT3: 0.11183898 | AU3: 0.087991527 | AW3: 1 | AX3: Fully supplemented 24h | AY3: 16659759 | AZ3: 636057.02 | BA3: 0 | BC3: Fully supplemented 24h | BD3: =AY3/$AT3 -> 1.48962e+08 | BE3: =AZ3/$AT3 -> 5687256.7 | BF3: =BA3/$AT3 -> 0
A4: 2 | B4: Fully supplemented 24h | C4: 24368.542 | D4: 45280.559 | E4: 1812859.1 | F4: 5395823.5 | G4: 0 | H4: 2757075.3 | I4: 6458862.9 | J4: 1937765.3 | K4: 97758.374 | M4: Intercept, b | N4: ='Calibration curve'!B12 -> -623883.2 | O4: ='Calibration curve'!C12 -> -258699.6 | P4: ='Calibration curve'!D12 -> -118328.4 | Q4: ='Calibration curve'!E12 -> -1756728.2 | S4: 2 | T4: Fully supplemented 24h | U4: =(C4-$N$4)/$N$3 -> 0.058447733 | V4: =(D4-$O$12)/$O$11 -> 0.060825236 | W4: =(F4-$O$4)/$O$3 -> 0.46674623 | X4: 0 | Y4: =(H4-$P$8)/$P$7 -> 0.66103656 | Z4: =(I4-$P$4)/$P$3 -> 3.4219301 | AA4: =(J4-$Q$4)/$Q$3 -> 0.19068498 | AB4: =(K4-$N$19)/$N$18 -> 0.20499739 | AD4: 2 | AE4: Fully supplemented 24h | AF4: =(U4*0.0005*1000) /$AU$3 -> 0.33212137 | AG4: =(V4*0.0005*1000) /$AU4 -> 0.34563121 | AH4: =(W4*0.0005*1000) /$AU4 -> 2.6522226 | AI4: =(X4*0.0005*1000) /$AU4 -> 0 | AJ4: =(Y4*0.0005*1000) /$AU4 -> 3.7562512 | AK4: =(Z4*0.0005*1000) /$AU4 -> 19.444657 | AL4: =(AA4*0.0005*1000) /$AU4 -> 1.0835417 | AM4: =(AB4*0.0005*1000) /$AU4 -> 1.16487 | AP4: 2 | AQ4: 0.30756666 | AR4: 0.17486667 | AS4: 0.26824859 | AT4: 0.080474576 | AU4: 0.087991527 | AW4: 2 | AX4: Fully supplemented 24h | AY4: 17523720 | AZ4: 811243.28 | BA4: 0 | BC4: Fully supplemented 24h | BD4: =AY4/$AT4 -> 2.1775474e+08 | BE4: =AZ4/$AT4 -> 10080740 | BF4: =BA4/$AT4 -> 0
A5: 3 | B5: Fully supplemented 24h | C5: 31582.57 | D5: 47426.994 | E5: 4330230.9 | F5: 5817777 | G5: 0 | H5: 3393989.2 | I5: 5581503.8 | J5: 1725546 | K5: 100310.81 | S5: 3 | T5: Fully supplemented 24h | U5: =(C5-$N$4)/$N$3 -> 0.059098165 | V5: =(D5-$O$12)/$O$11 -> 0.061044727 | W5: =(F5-$O$4)/$O$3 -> 0.50157591 | X5: 0 | Y5: =(H5-$P$8)/$P$7 -> 0.78752517 | Z5: =(I5-$P$4)/$P$3 -> 2.9654645 | AA5: =(J5-$Q$4)/$Q$3 -> 0.17973164 | AB5: =(K5-$N$19)/$N$18 -> 0.21102325 | AD5: 3 | AE5: Fully supplemented 24h | AF5: =(U5*0.0005*1000) /$AU$3 -> 0.33581736 | AG5: =(V5*0.0005*1000) /$AU5 -> 0.34687844 | AH5: =(W5*0.0005*1000) /$AU5 -> 2.8501376 | AI5: =(X5*0.0005*1000) /$AU5 -> 0 | AJ5: =(Y5*0.0005*1000) /$AU5 -> 4.4750057 | AK5: =(Z5*0.0005*1000) /$AU5 -> 16.850852 | AL5: =(AA5*0.0005*1000) /$AU5 -> 1.0213008 | AM5: =(AB5*0.0005*1000) /$AU5 -> 1.1991112 | AP5: 3 | AQ5: 0.29023333 | AR5: 0.15753334 | AS5: 0.23887006 | AT5: 0.071661019 | AU5: 0.087991527 | AW5: 3 | AX5: Fully supplemented 24h | AY5: 19277570 | AZ5: 1004545.2 | BA5: 4414.9022 | BC5: Fully supplemented 24h | BD5: =AY5/$AT5 -> 2.6901054e+08 | BE5: =AZ5/$AT5 -> 14018015 | BF5: =BA5/$AT5 -> 61608.142
A6: 4 | B6: w/o B2, B3, B5 24h | C6: 14045.648 | D6: 53937.083 | E6: 11624414 | F6: 2530517.3 | G6: 0 | H6: 4295394.3 | I6: 3800643.3 | J6: 1663980.3 | K6: 32193.447 | N6: FMN | O6: CoA | P6: ADP | S6: 4 | T6: w/o B2, B3, B5 24h | U6: =(C6-$N$4)/$N$3 -> 0.057516999 | V6: =(D6-$O$12)/$O$11 -> 0.061710437 | W6: =(F6-$O$4)/$O$3 -> 0.23023277 | X6: 0 | Y6: =(H6-$P$8)/$P$7 -> 0.96654071 | Z6: =(I6-$P$4)/$P$3 -> 2.0389322 | AA6: =(J6-$Q$4)/$Q$3 -> 0.17655404 | AB6: =(K6-$N$19)/$N$18 -> 0.05020997 | AD6: 4 | AE6: w/o B2, B3, B5 24h | AF6: =(U6*0.0005*1000) / $AU$6 -> 0.33595712 | AG6: =(V6*0.0005*1000) /$AU6 -> 0.36045101 | AH6: =(W6*0.0005*1000) /$AU6 -> 1.3447909 | AI6: =(X6*0.0005*1000) /$AU6 -> 0 | AJ6: =(Y6*0.0005*1000) /$AU6 -> 5.6455698 | AK6: =(Z6*0.0005*1000) /$AU6 -> 11.909415 | AL6: =(AA6*0.0005*1000) /$AU6 -> 1.0312531 | AM6: =(AB6*0.0005*1000) /$AU6 -> 0.29327672 | AP6: 4 | AQ6: 0.31936666 | AR6: 0.18666667 | AS6: 0.28824859 | AT6: 0.086474577 | AU6: 0.085601697 | AW6: 4 | AX6: w/o B2, B3, B5 24h | AY6: 3598273.1 | AZ6: 206003.08 | BA6: 0 | BC6: w/o B2, B3, B5 24h | BD6: =AY6/$AT6 -> 41610763 | BE6: =AZ6/$AT6 -> 2382238.7 | BF6: =BA6/$AT6 -> 0
A7: 5 | B7: w/o B2, B3, B5 24h | C7: 20195.583 | D7: 84822.216 | E7: 19253228 | F7: 3596021.2 | G7: 0 | H7: 5841664.1 | I7: 4924612.6 | J7: 2342424.7 | K7: 46949.288 | M7: Slope, m | N7: ='Calibration curve'!B25 -> 11920690 | O7: ='Calibration curve'!C25 -> 722610.98 | P7: ='Calibration curve'!D25 -> 5035345.5 | S7: 5 | T7: w/o B2, B3, B5 24h | U7: =(C7-$N$4)/$N$3 -> 0.05807149 | V7: =(D7-$O$12)/$O$11 -> 0.064868697 | W7: =(F7-$O$4)/$O$3 -> 0.31818358 | X7: 0 | Y7: =(H7-$P$8)/$P$7 -> 1.2736239 | Z7: =(I7-$P$4)/$P$3 -> 2.6237022 | AA7: =(J7-$Q$4)/$Q$3 -> 0.21157078 | AB7: =(K7-$N$19)/$N$18 -> 0.08504595 | AD7: 5 | AE7: w/o B2, B3, B5 24h | AF7: =(U7*0.0005*1000) / $AU$6 -> 0.33919591 | AG7: =(V7*0.0005*1000) /$AU7 -> 0.37889843 | AH7: =(W7*0.0005*1000) /$AU7 -> 1.8585121 | AI7: =(X7*0.0005*1000) /$AU7 -> 0 | AJ7: =(Y7*0.0005*1000) /$AU7 -> 7.4392442 | AK7: =(Z7*0.0005*1000) /$AU7 -> 15.32506 | AL7: =(AA7*0.0005*1000) /$AU7 -> 1.2357862 | AM7: =(AB7*0.0005*1000) /$AU7 -> 0.49675388 | AP7: 5 | AQ7: 0.31593334 | AR7: 0.18323334 | AS7: 0.28242939 | AT7: 0.084728817 | AU7: 0.085601697 | AW7: 5 | AX7: w/o B2, B3, B5 24h | AY7: 3776005.6 | AZ7: 270496.59 | BA7: 0 | BC7: w/o B2, B3, B5 24h | BD7: =AY7/$AT7 -> 44565777 | BE7: =AZ7/$AT7 -> 3192498.1 | BF7: =BA7/$AT7 -> 0
A8: 6 | B8: w/o B2, B3, B5 24h | C8: 8534.5758 | D8: 53556.206 | E8: 19605768 | F8: 2789562.9 | G8: 0 | H8: 4958380.2 | I8: 3246120.2 | J8: 2174675.6 | K8: 43420.215 | M8: Intercept, b | N8: ='Calibration curve'!B26 -> -570892.4 | O8: ='Calibration curve'!C26 -> -665300.71 | P8: ='Calibration curve'!D26 -> -571472.12 | S8: 6 | T8: w/o B2, B3, B5 24h | U8: =(C8-$N$4)/$N$3 -> 0.05702011 | V8: =(D8-$O$12)/$O$11 -> 0.061671489 | W8: =(F8-$O$4)/$O$3 -> 0.25161539 | X8: 0 | Y8: =(H8-$P$8)/$P$7 -> 1.0982071 | Z8: =(I8-$P$4)/$P$3 -> 1.7504292 | AA8: =(J8-$Q$4)/$Q$3 -> 0.2029127 | AB8: =(K8-$N$19)/$N$18 -> 0.076714421 | AD8: 6 | AE8: w/o B2, B3, B5 24h | AF8: =(U8*0.0005*1000) / $AU$6 -> 0.33305479 | AG8: =(V8*0.0005*1000) /$AU8 -> 0.36022352 | AH8: =(W8*0.0005*1000) /$AU8 -> 1.4696869 | AI8: =(X8*0.0005*1000) /$AU8 -> 0 | AJ8: =(Y8*0.0005*1000) /$AU8 -> 6.4146341 | AK8: =(Z8*0.0005*1000) /$AU8 -> 10.224267 | AL8: =(AA8*0.0005*1000) /$AU8 -> 1.1852142 | AM8: =(AB8*0.0005*1000) /$AU8 -> 0.44808937 | AP8: 6 | AQ8: 0.21596666 | AR8: 0.083266666 | AS8: 0.11299435 | AT8: 0.033898305 | AU8: 0.085601697 | AW8: 6 | AX8: w/o B2, B3, B5 24h | AY8: 3316158.3 | AZ8: 242142.74 | BA8: 0 | BC8: w/o B2, B3, B5 24h | BD8: =AY8/$AT8 -> 97826672 | BE8: =AZ8/$AT8 -> 7143210.9 | BF8: =BA8/$AT8 -> 0
A9: 7 | B9: Without B3 24h | C9: 29026.431 | D9: 51875.81 | E9: 522244.75 | F9: 3220476.6 | G9: 0 | H9: 1741403.4 | I9: 7818457.9 | J9: 2514233.7 | K9: 38908.555 | S9: 7 | T9: Without B3 24h | U9: =(C9-$N$4)/$N$3 -> 0.058867698 | V9: =(D9-$O$12)/$O$11 -> 0.061499655 | W9: =(F9-$O$4)/$O$3 -> 0.28718468 | X9: 0 | Y9: =(H9-$P$8)/$P$7 -> 0.45932808 | Z9: =(I9-$P$4)/$P$3 -> 4.1292896 | AA9: =(J9-$Q$4)/$Q$3 -> 0.22043841 | AB9: =(K9-$N$19)/$N$18 -> 0.066063174 | AD9: 7 | AE9: Without B3 24h | AF9: =(U9*0.0005*1000) /$AU$9 -> 0.53212719 | AG9: =(V9*0.0005*1000) /$AU9 -> 0.55591843 | AH9: =(W9*0.0005*1000) /$AU9 -> 2.5959699 | AI9: =(X9*0.0005*1000) /$AU9 -> 0 | AJ9: =(Y9*0.0005*1000) /$AU9 -> 4.1520386 | AK9: =(Z9*0.0005*1000) /$AU9 -> 37.326196 | AL9: =(AA9*0.0005*1000) /$AU9 -> 1.9926254 | AM9: =(AB9*0.0005*1000) /$AU9 -> 0.59716979 | AP9: 7 | AQ9: 0.268 | AR9: 0.1353 | AS9: 0.20118644 | AT9: 0.060355932 | AU9: =AVERAGE(AT11,Table3[[#This Row],[Total protein mg]]) -> 0.05531356 | AW9: 7 | AX9: Without B3 24h | AY9: 18287001 | AZ9: 217237.09 | BA9: 0 | BC9: Without B3 24h | BD9: =AY9/$AT9 -> 3.0298597e+08 | BE9: =AZ9/$AT9 -> 3599266.6 | BF9: =BA9/$AT9 -> 0
A10: 8 | B10: Without B3 24h | C10: 32899.703 | D10: 54251.246 | E10: 595941.21 | F10: 3376189.5 | G10: 0 | H10: 1864806.8 | I10: 7938589.7 | J10: 2422343.7 | K10: 42385.261 | N10: cFMN | O10: AceCoA | P10: AMP | S10: 8 | T10: Without B3 24h | U10: =(C10-$N$4)/$N$3 -> 0.05921692 | V10: =(D10-$O$12)/$O$11 -> 0.061742563 | W10: =(F10-$O$4)/$O$3 -> 0.30003782 | X10: 0 | Y10: =(H10-$P$8)/$P$7 -> 0.48383551 | Z10: =(I10-$P$4)/$P$3 -> 4.1917909 | AA10: =(J10-$Q$4)/$Q$3 -> 0.21569567 | AB10: =(K10-$N$19)/$N$18 -> 0.074271075 | AD10: 8 | AE10: Without B3 24h | AF10: =(U10*0.0005*1000) /$AU$9 -> 0.53528394 | AG10: =(V10*0.0005*1000) /$AU10 -> 0.55811416 | AH10: =(W10*0.0005*1000) /$AU10 -> 2.7121543 | AI10: =(X10*0.0005*1000) /$AU10 -> 0 | AJ10: =(Y10*0.0005*1000) /$AU10 -> 4.3735705 | AK10: =(Z10*0.0005*1000) /$AU10 -> 37.891168 | AL10: =(AA10*0.0005*1000) /$AU10 -> 1.949754 | AM10: =(AB10*0.0005*1000) /$AU10 -> 0.67136408 | AP10: 8 | AQ10: 0.36406667 | AR10: 0.23136667 | AS10: 0.36401131 | AT10: 0.10920339 | AU10: 0.05531356 | AW10: 8 | AX10: Without B3 24h | AY10: 21173956 | AZ10: 463399.36 | BA10: 0 | BC10: Without B3 24h | BD10: =AY10/$AT10 -> 1.9389467e+08 | BE10: =AZ10/$AT10 -> 4243452 | BF10: =BA10/$AT10 -> 0
A11: 9 | B11: Without B3 24h | C11: 30980.766 | D11: 51274.573 | E11: 841256.7 | F11: 3480991.9 | G11: 0 | H11: 1955867.1 | I11: 8574294.7 | J11: 2505768.6 | K11: 45065.537 | M11: Slope, m | N11: ='Calibration curve'!B39 -> 20131434 | O11: ='Calibration curve'!C39 -> 9779161 | P11: ='Calibration curve'!D39 -> 20509113 | S11: 9 | T11: Without B3 24h | U11: =(C11-$N$4)/$N$3 -> 0.059043905 | V11: =(D11-$O$12)/$O$11 -> 0.061438173 | W11: =(F11-$O$4)/$O$3 -> 0.30868862 | X11: 0 | Y11: =(H11-$P$8)/$P$7 -> 0.50191972 | Z11: =(I11-$P$4)/$P$3 -> 4.5225305 | AA11: =(J11-$Q$4)/$Q$3 -> 0.2200015 | AB11: =(K11-$N$19)/$N$18 -> 0.080598742 | AD11: 9 | AE11: Without B3 24h | AF11: =(U11*0.0005*1000) /$AU$9 -> 0.53371999 | AG11: =(V11*0.0005*1000) /$AU11 -> 0.55536267 | AH11: =(W11*0.0005*1000) /$AU11 -> 2.7903521 | AI11: =(X11*0.0005*1000) /$AU11 -> 0 | AJ11: =(Y11*0.0005*1000) /$AU11 -> 4.5370404 | AK11: =(Z11*0.0005*1000) /$AU11 -> 40.880848 | AL11: =(AA11*0.0005*1000) /$AU11 -> 1.988676 | AM11: =(AB11*0.0005*1000) /$AU11 -> 0.72856224 | AP11: 9 | AQ11: 0.24816667 | AR11: 0.11546667 | AS11: 0.16757063 | AT11: 0.050271188 | AU11: 0.05531356 | AW11: 9 | AX11: Without B3 24h | AY11: 21001155 | AZ11: 234769.04 | BA11: 2724.1156 | BC11: Without B3 24h | BD11: =AY11/$AT11 -> 4.1775728e+08 | BE11: =AZ11/$AT11 -> 4670051.6 | BF11: =BA11/$AT11 -> 54188.407
A12: 10 | B12: Without B5 24h | C12: 26245.796 | D12: 42067.048 | E12: 523529.95 | F12: 6242309 | G12: 0 | H12: 1883084.9 | I12: 7054215.2 | J12: 2737751.4 | K12: 74879.587 | M12: Intercept, b | N12: ='Calibration curve'!B40 -> 2979154.4 | O12: ='Calibration curve'!C40 -> -549539.21 | P12: ='Calibration curve'!D40 -> 4378658.7 | S12: 10 | T12: Without B5 24h | U12: =(C12-$N$4)/$N$3 -> 0.05861699 | V12: =(D12-$O$12)/$O$11 -> 0.060496628 | W12: =(F12-$O$4)/$O$3 -> 0.53661842 | X12: 0 | Y12: =(H12-$P$8)/$P$7 -> 0.48746546 | Z12: =(I12-$P$4)/$P$3 -> 3.7316753 | AA12: =(J12-$Q$4)/$Q$3 -> 0.2319749 | AB12: =(K12-$N$19)/$N$18 -> 0.15098454 | AD12: 10 | AE12: Without B5 24h | AF12: =(U12*0.0005*1000) /$AU$12 -> 0.28349884 | AG12: =(V12*0.0005*1000) /$AU12 -> 0.29258963 | AH12: =(W12*0.0005*1000) /$AU12 -> 2.5953345 | AI12: =(X12*0.0005*1000) /$AU12 -> 0 | AJ12: =(Y12*0.0005*1000) /$AU12 -> 2.3576081 | AK12: =(Z12*0.0005*1000) /$AU12 -> 18.048106 | AL12: =(AA12*0.0005*1000) /$AU12 -> 1.1219378 | AM12: =(AB12*0.0005*1000) /$AU12 -> 0.73023098 | AP12: 10 | AQ12: 0.2227 | AR12: 0.090000004 | AS12: 0.12440679 | AT12: 0.037322036 | AU12: 0.10338136 | AW12: 10 | AX12: Without B5 24h | AY12: 17325204 | AZ12: 2324404.2 | BA12: 849349.89 | BC12: Without B5 24h | BD12: =AY12/$AT12 -> 4.6420845e+08 | BE12: =AZ12/$AT12 -> 62279673 | BF12: =BA12/$AT12 -> 22757330
A13: 11 | B13: Without B5 24h | C13: 25975.377 | D13: 49825.874 | E13: 471835.41 | F13: 5535945.6 | G13: 0 | H13: 1613109.2 | I13: 6606827.8 | J13: 2319708.7 | K13: 63870.664 | S13: 11 | T13: Without B5 24h | U13: =(C13-$N$4)/$N$3 -> 0.058592609 | V13: =(D13-$O$12)/$O$11 -> 0.061290032 | W13: =(F13-$O$4)/$O$3 -> 0.47831245 | X13: 0 | Y13: =(H13-$P$8)/$P$7 -> 0.43384934 | Z13: =(I13-$P$4)/$P$3 -> 3.4989121 | AA13: =(J13-$Q$4)/$Q$3 -> 0.21039834 | AB13: =(K13-$N$19)/$N$18 -> 0.12499438 | AD13: 11 | AE13: Without B5 24h | AF13: =(U13*0.0005*1000) /$AU$12 -> 0.28338092 | AG13: =(V13*0.0005*1000) /$AU13 -> 0.2964269 | AH13: =(W13*0.0005*1000) /$AU13 -> 2.3133399 | AI13: =(X13*0.0005*1000) /$AU13 -> 0 | AJ13: =(Y13*0.0005*1000) /$AU13 -> 2.0982958 | AK13: =(Z13*0.0005*1000) /$AU13 -> 16.922355 | AL13: =(AA13*0.0005*1000) /$AU13 -> 1.0175835 | AM13: =(AB13*0.0005*1000) /$AU13 -> 0.60453058 | AP13: 11 | AQ13: 0.34586666 | AR13: 0.21316666 | AS13: 0.33316384 | AT13: 0.099949151 | AU13: 0.10338136 | AW13: 11 | AX13: Without B5 24h | AY13: 14609645 | AZ13: 1796839.6 | BA13: 554884.18 | BC13: Without B5 24h | BD13: =AY13/$AT13 -> 1.4617078e+08 | BE13: =AZ13/$AT13 -> 17977537 | BF13: =BA13/$AT13 -> 5551664.8
A14: 12 | B14: Without B5 24h | C14: 24707.941 | D14: 60967.033 | E14: 649339.44 | F14: 6309735.8 | G14: 0 | H14: 1750340.3 | I14: 6929833.9 | J14: 2558995.6 | K14: 100345.93 | N14: Y+mX+b | O14: y = ax + b | S14: 12 | T14: Without B5 24h | U14: =(C14-$N$4)/$N$3 -> 0.058478334 | V14: =(D14-$O$12)/$O$11 -> 0.062429307 | W14: =(F14-$O$4)/$O$3 -> 0.5421841 | X14: 0 | Y14: =(H14-$P$8)/$P$7 -> 0.46110291 | Z14: =(I14-$P$4)/$P$3 -> 3.6669632 | AA14: =(J14-$Q$4)/$Q$3 -> 0.22274872 | AB14: =(K14-$N$19)/$N$18 -> 0.21110617 | AD14: 12 | AE14: Without B5 24h | AF14: =(U14*0.0005*1000) /$AU$12 -> 0.28282823 | AG14: =(V14*0.0005*1000) /$AU14 -> 0.30193697 | AH14: =(W14*0.0005*1000) /$AU14 -> 2.6222527 | AI14: =(X14*0.0005*1000) /$AU14 -> 0 | AJ14: =(Y14*0.0005*1000) /$AU14 -> 2.2301067 | AK14: =(Z14*0.0005*1000) /$AU14 -> 17.735128 | AL14: =(AA14*0.0005*1000) /$AU14 -> 1.0773157 | AM14: =(AB14*0.0005*1000) /$AU14 -> 1.0210069 | AP14: 12 | AQ14: 0.35936668 | AR14: 0.22666668 | AS14: 0.35604522 | AT14: 0.10681357 | AU14: 0.10338136 | AW14: 12 | AX14: Without B5 24h | AY14: 15307385 | AZ14: 4887364.1 | BA14: 1172735.2 | BC14: Without B5 24h | BD14: =AY14/$AT14 -> 1.4330937e+08 | BE14: =AZ14/$AT14 -> 45756024 | BF14: =BA14/$AT14 -> 10979272
A15: 13 | B15: Fully supplemented 72h | C15: 105102.99 | D15: 145274.83 | E15: 2964461.2 | F15: 17329017 | G15: 7564.8613 | H15: 5958019 | I15: 25289587 | J15: 6236433.5 | K15: 167275.31 | N15: X=(Y-b)/m | O15: x = (y-b)/a | S15: 13 | T15: Fully supplemented 72h | U15: =(C15-$N$4)/$N$3 -> 0.06572692 | V15: =(D15-$O$12)/$O$11 -> 0.071050476 | W15: =(F15-$O$4)/$O$3 -> 1.4517582 | X15: =(G15-$O$8)/$O$7 -> 0.9311588 | Y15: =(H15-$P$8)/$P$7 -> 1.2967315 | Z15: =(I15-$P$4)/$P$3 -> 13.219033 | AA15: =(J15-$Q$4)/$Q$3 -> 0.41255341 | AB15: =(K15-$N$19)/$N$18 -> 0.36911481 | AD15: 13 | AE15: Fully supplemented 72h | AF15: =(U15*0.0005*1000) /$AU$15 -> 0.28693925 | AG15: =(V15*0.0005*1000) /$AU15 -> 0.31017991 | AH15: =(W15*0.0005*1000) /$AU15 -> 6.3378355 | AI15: =(X15*0.0005*1000) /$AU15 -> 4.0650925 | AJ15: =(Y15*0.0005*1000) /$AU15 -> 5.6610467 | AK15: =(Z15*0.0005*1000) /$AU15 -> 57.709375 | AL15: =(AA15*0.0005*1000) /$AU15 -> 1.8010545 | AM15: =(AB15*0.0005*1000) /$AU15 -> 1.6114178 | AP15: 13 | AQ15: 0.38839999 | AR15: 0.25569999 | AS15: 0.40525422 | AT15: 0.12157627 | AU15: 0.11453107 | AW15: 13 | AX15: Fully supplemented 72h | AY15: 43410615 | AZ15: 9986497.9 | BA15: 3829.1186 | BC15: Fully supplemented 72h | BD15: =AY15/$AT15 -> 3.5706487e+08 | BE15: =AZ15/$AT15 -> 82141837 | BF15: =BA15/$AT15 -> 31495.61
A16: 14 | B16: Fully supplemented 72h | C16: 90972.873 | D16: 141292.13 | E16: 3005698.3 | F16: 14914633 | G16: 14489.302 | H16: 5305437.2 | I16: 20776974 | J16: 4730748.6 | K16: 164340.5 | S16: 14 | T16: Fully supplemented 72h | U16: =(C16-$N$4)/$N$3 -> 0.064452919 | V16: =(D16-$O$12)/$O$11 -> 0.070643213 | W16: =(F16-$O$4)/$O$3 -> 1.2524656 | X16: =(G16-$O$8)/$O$7 -> 0.94074132 | Y16: =(H16-$P$8)/$P$7 -> 1.1671313 | Z16: =(I16-$P$4)/$P$3 -> 10.871246 | AA16: =(J16-$Q$4)/$Q$3 -> 0.33484005 | AB16: =(K16-$N$19)/$N$18 -> 0.36218625 | AD16: 14 | AE16: Fully supplemented 72h | AF16: =(U16*0.0005*1000) /$AU$15 -> 0.28137744 | AG16: =(V16*0.0005*1000) /$AU16 -> 0.30840195 | AH16: =(W16*0.0005*1000) /$AU16 -> 5.4677983 | AI16: =(X16*0.0005*1000) /$AU16 -> 4.1069262 | AJ16: =(Y16*0.0005*1000) /$AU16 -> 5.0952605 | AK16: =(Z16*0.0005*1000) /$AU16 -> 47.45981 | AL16: =(AA16*0.0005*1000) /$AU16 -> 1.4617869 | AM16: =(AB16*0.0005*1000) /$AU16 -> 1.5811702 | AP16: 14 | AQ16: 0.35729999 | AR16: 0.2246 | AS16: 0.35254237 | AT16: 0.10576271 | AU16: 0.11453107 | AW16: 14 | AX16: Fully supplemented 72h | AY16: 31649421 | AZ16: 2822613.4 | BA16: 0 | BC16: Fully supplemented 72h | BD16: =AY16/$AT16 -> 2.9924933e+08 | BE16: =AZ16/$AT16 -> 26688172 | BF16: =BA16/$AT16 -> 0
A17: 15 | B17: Fully supplemented 72h | C17: 112772.15 | D17: 188636.54 | E17: 3901031 | F17: 18258680 | G17: 32028.068 | H17: 6175576.8 | I17: 24978352 | J17: 5580506.1 | K17: 167511.87 | N17: ADRR | S17: 15 | T17: Fully supplemented 72h | U17: =(C17-$N$4)/$N$3 -> 0.066418387 | V17: =(D17-$O$12)/$O$11 -> 0.075484569 | W17: =(F17-$O$4)/$O$3 -> 1.5284962 | X17: =(G17-$O$8)/$O$7 -> 0.96501271 | Y17: =(H17-$P$8)/$P$7 -> 1.3399376 | Z17: =(I17-$P$4)/$P$3 -> 13.057106 | AA17: =(J17-$Q$4)/$Q$3 -> 0.37869883 | AB17: =(K17-$N$19)/$N$18 -> 0.36967329 | AD17: 15 | AE17: Fully supplemented 72h | AF17: =(U17*0.0005*1000) /$AU$15 -> 0.28995794 | AG17: =(V17*0.0005*1000) /$AU17 -> 0.32953751 | AH17: =(W17*0.0005*1000) /$AU17 -> 6.6728452 | AI17: =(X17*0.0005*1000) /$AU17 -> 4.212886 | AJ17: =(Y17*0.0005*1000) /$AU17 -> 5.8496686 | AK17: =(Z17*0.0005*1000) /$AU17 -> 57.002461 | AL17: =(AA17*0.0005*1000) /$AU17 -> 1.653258 | AM17: =(AB17*0.0005*1000) /$AU17 -> 1.6138559 | AP17: 15 | AQ17: 0.37793333 | AR17: 0.24523334 | AS17: 0.38751413 | AT17: 0.11625424 | AU17: 0.11453107 | AW17: 15 | AX17: Fully supplemented 72h | AY17: 42177787 | AZ17: 3357727 | BA17: 0 | BC17: Fully supplemented 72h | BD17: =AY17/$AT17 -> 3.6280644e+08 | BE17: =AZ17/$AT17 -> 28882620 | BF17: =BA17/$AT17 -> 0
A18: 16 | B18: w/o B2, B3, B5 72h | C18: 21154.834 | D18: 224567.49 | E18: 89950659 | F18: 2543271.9 | G18: 0 | H18: 15041185 | I18: 6994559 | J18: 6457947.5 | K18: 28312.309 | M18: Slope, m | N18: ='Calibration curve'!B54 -> 423580.47 | S18: 16 | T18: w/o B2, B3, B5 72h | U18: =(C18-$N$4)/$N$3 -> 0.058157978 | V18: =(D18-$O$12)/$O$11 -> 0.079158806 | W18: =(F18-$O$4)/$O$3 -> 0.23128558 | X18: =(G18-$O$8)/$O$7 -> 0.92069001 | Y18: =(H18-$P$8)/$P$7 -> 3.1006128 | Z18: =(I18-$P$4)/$P$3 -> 3.7006379 | AA18: =(J18-$Q$4)/$Q$3 -> 0.42398647 | AB18: =(K18-$N$19)/$N$18 -> 0.041047276 | AD18: 16 | AE18: w/o B2, B3, B5 72h | AF18: =(U18*0.0005*1000) /$AU$18 -> 0.30518713 | AG18: =(V18*0.0005*1000) /$AU18 -> 0.41539011 | AH18: =(W18*0.0005*1000) /$AU18 -> 1.2136836 | AI18: =(X18*0.0005*1000) /$AU18 -> 4.8313705 | AJ18: =(Y18*0.0005*1000) /$AU18 -> 16.270633 | AK18: =(Z18*0.0005*1000) /$AU18 -> 19.419297 | AL18: =(AA18*0.0005*1000) /$AU18 -> 2.2248919 | AM18: =(AB18*0.0005*1000) /$AU18 -> 0.2153978 | AP18: 16 | AQ18: 0.3617 | AR18: 0.229 | AS18: 0.36 | AT18: 0.108 | AU18: 0.095282488 | AW18: 16 | AX18: w/o B2, B3, B5 72h | AY18: 2895570.1 | AZ18: 301277.85 | BA18: 0 | BC18: w/o B2, B3, B5 72h | BD18: =AY18/$AT18 -> 26810834 | BE18: =AZ18/$AT18 -> 2789609.7 | BF18: =BA18/$AT18 -> 0
A19: 17 | B19: w/o B2, B3, B5 72h | C19: 9906.9122 | D19: 182002.42 | E19: 55929836 | F19: 1874481.3 | G19: 3696.4525 | H19: 13486419 | I19: 8176087.5 | J19: 5740082.6 | K19: 29621.347 | M19: Intercept, b | N19: ='Calibration curve'!B55 -> 10925.484 | S19: 17 | T19: w/o B2, B3, B5 72h | U19: =(C19-$N$4)/$N$3 -> 0.057143842 | V19: =(D19-$O$12)/$O$11 -> 0.074806176 | W19: =(F19-$O$4)/$O$3 -> 0.17608101 | X19: =(G19-$O$8)/$O$7 -> 0.92580542 | Y19: =(H19-$P$8)/$P$7 -> 2.7918425 | Z19: =(I19-$P$4)/$P$3 -> 4.3153543 | AA19: =(J19-$Q$4)/$Q$3 -> 0.3869351 | AB19: =(K19-$N$19)/$N$18 -> 0.044137688 | AD19: 17 | AE19: w/o B2, B3, B5 72h | AF19: =(U19*0.0005*1000) /$AU$18 -> 0.2998654 | AG19: =(V19*0.0005*1000) /$AU19 -> 0.39254945 | AH19: =(W19*0.0005*1000) /$AU19 -> 0.92399461 | AI19: =(X19*0.0005*1000) /$AU19 -> 4.8582139 | AJ19: =(Y19*0.0005*1000) /$AU19 -> 14.650344 | AK19: =(Z19*0.0005*1000) /$AU19 -> 22.645055 | AL19: =(AA19*0.0005*1000) /$AU19 -> 2.0304628 | AM19: =(AB19*0.0005*1000) /$AU19 -> 0.2316149 | AP19: 17 | AQ19: 0.33179999 | AR19: 0.1991 | AS19: 0.30932203 | AT19: 0.092796609 | AU19: 0.095282488 | AW19: 17 | AX19: w/o B2, B3, B5 72h | AY19: 3041357 | AZ19: 149062.73 | BA19: 0 | BC19: w/o B2, B3, B5 72h | BD19: =AY19/$AT19 -> 32774442 | BE19: =AZ19/$AT19 -> 1606338.1 | BF19: =BA19/$AT19 -> 0
A20: 18 | B20: w/o B2, B3, B5 72h | C20: 12580.15 | D20: 202871.83 | E20: 53428191 | F20: 2238974.3 | G20: 6163.8311 | H20: 15361678 | I20: 11942185 | J20: 6684884.3 | K20: 23409.427 | S20: 18 | T20: w/o B2, B3, B5 72h | U20: =(C20-$N$4)/$N$3 -> 0.057384867 | V20: =(D20-$O$12)/$O$11 -> 0.076940245 | W20: =(F20-$O$4)/$O$3 -> 0.20616767 | X20: =(G20-$O$8)/$O$7 -> 0.92921995 | Y20: =(H20-$P$8)/$P$7 -> 3.1642615 | Z20: =(I20-$P$4)/$P$3 -> 6.2747502 | AA20: =(J20-$Q$4)/$Q$3 -> 0.43569943 | AB20: =(K20-$N$19)/$N$18 -> 0.029472423 | AD20: 18 | AE20: w/o B2, B3, B5 72h | AF20: =(U20*0.0005*1000) /$AU$18 -> 0.30113019 | AG20: =(V20*0.0005*1000) /$AU20 -> 0.40374809 | AH20: =(W20*0.0005*1000) /$AU20 -> 1.081876 | AI20: =(X20*0.0005*1000) /$AU20 -> 4.8761319 | AJ20: =(Y20*0.0005*1000) /$AU20 -> 16.604633 | AK20: =(Z20*0.0005*1000) /$AU20 -> 32.927091 | AL20: =(AA20*0.0005*1000) /$AU20 -> 2.2863563 | AM20: =(AB20*0.0005*1000) /$AU20 -> 0.15465813 | AP20: 18 | AQ20: 0.31656668 | AR20: 0.18386668 | AS20: 0.28350285 | AT20: 0.085050854 | AU20: 0.095282488 | AW20: 18 | AX20: w/o B2, B3, B5 72h | AY20: 3019195.1 | AZ20: 287361.01 | BA20: 0 | BC20: w/o B2, B3, B5 72h | BD20: =AY20/$AT20 -> 35498704 | BE20: =AZ20/$AT20 -> 3378696.4 | BF20: =BA20/$AT20 -> 0
A21: 19 | B21: Without B3 72h | C21: 108111.5 | D21: 169540.44 | E21: 2284815.4 | F21: 2334964.3 | G21: 24414.342 | H21: 3997091.6 | I21: 24613770 | J21: 6788950.1 | K21: 30100.693 | S21: 19 | T21: Without B3 72h | U21: =(C21-$N$4)/$N$3 -> 0.065998173 | V21: =(D21-$O$12)/$O$11 -> 0.073531835 | W21: =(F21-$O$4)/$O$3 -> 0.21409106 | X21: =(G21-$O$8)/$O$7 -> 0.95447629 | Y21: =(H21-$P$8)/$P$7 -> 0.90729895 | Z21: =(I21-$P$4)/$P$3 -> 12.867424 | AA21: =(J21-$Q$4)/$Q$3 -> 0.44107061 | AB21: =(K21-$N$19)/$N$18 -> 0.04526934 | AD21: 19 | AE21: Without B3 72h | AF21: =(U21*0.0005*1000) /$AU$21 -> 0.26321939 | AG21: =(V21*0.0005*1000) /$AU21 -> 0.29326576 | AH21: =(W21*0.0005*1000) /$AU21 -> 0.85385573 | AI21: =(X21*0.0005*1000) /$AU21 -> 3.8067215 | AJ21: =(Y21*0.0005*1000) /$AU21 -> 3.6185649 | AK21: =(Z21*0.0005*1000) /$AU21 -> 51.318928 | AL21: =(AA21*0.0005*1000) /$AU21 -> 1.7591144 | AM21: =(AB21*0.0005*1000) /$AU21 -> 0.18054694 | AP21: 19 | AQ21: 0.41043333 | AR21: 0.27773334 | AS21: 0.44259887 | AT21: 0.13277966 | AU21: 0.12536723 | AW21: 19 | AX21: Without B3 72h | AY21: 41245443 | AZ21: 157163.17 | BA21: 163361.46 | BC21: Without B3 72h | BD21: =AY21/$AT21 -> 3.1063073e+08 | BE21: =AZ21/$AT21 -> 1183638.9 | BF21: =BA21/$AT21 -> 1230319.9
A22: 20 | B22: Without B3 72h | C22: 122644.28 | D22: 185212.32 | E22: 1859867.5 | F22: 2413334.4 | G22: 28521.261 | H22: 4030649 | I22: 23942162 | J22: 7018329.7 | K22: 23835.545 | S22: 20 | T22: Without B3 72h | U22: =(C22-$N$4)/$N$3 -> 0.067308479 | V22: =(D22-$O$12)/$O$11 -> 0.075134414 | W22: =(F22-$O$4)/$O$3 -> 0.22056003 | X22: =(G22-$O$8)/$O$7 -> 0.96015974 | Y22: =(H22-$P$8)/$P$7 -> 0.91396332 | Z22: =(I22-$P$4)/$P$3 -> 12.518006 | AA22: =(J22-$Q$4)/$Q$3 -> 0.45290965 | AB22: =(K22-$N$19)/$N$18 -> 0.030478413 | AD22: 20 | AE22: Without B3 72h | AF22: =(U22*0.0005*1000) /$AU$21 -> 0.26844526 | AG22: =(V22*0.0005*1000) /$AU22 -> 0.2996573 | AH22: =(W22*0.0005*1000) /$AU22 -> 0.87965581 | AI22: =(X22*0.0005*1000) /$AU22 -> 3.8293887 | AJ22: =(Y22*0.0005*1000) /$AU22 -> 3.6451443 | AK22: =(Z22*0.0005*1000) /$AU22 -> 49.925348 | AL22: =(AA22*0.0005*1000) /$AU22 -> 1.8063318 | AM22: =(AB22*0.0005*1000) /$AU22 -> 0.12155654 | AP22: 20 | AQ22: 0.38776666 | AR22: 0.25506666 | AS22: 0.40418078 | AT22: 0.12125424 | AU22: 0.12536723 | AW22: 20 | AX22: Without B3 72h | AY22: 46959577 | AZ22: 294774.84 | BA22: 85931.502 | BC22: Without B3 72h | BD22: =AY22/$AT22 -> 3.8728195e+08 | BE22: =AZ22/$AT22 -> 2431047.7 | BF22: =BA22/$AT22 -> 708688.67
A23: 21 | B23: Without B3 72h | C23: 110561.14 | D23: 181199.31 | E23: 2332005 | F23: 2392320.1 | G23: 5168.5142 | H23: 3827055.9 | I23: 24472699 | J23: 6454376.1 | K23: 22298.426 | S23: 21 | T23: Without B3 72h | U23: =(C23-$N$4)/$N$3 -> 0.066219038 | V23: =(D23-$O$12)/$O$11 -> 0.074724051 | W23: =(F23-$O$4)/$O$3 -> 0.21882543 | X23: =(G23-$O$8)/$O$7 -> 0.92784256 | Y23: =(H23-$P$8)/$P$7 -> 0.87353053 | Z23: =(I23-$P$4)/$P$3 -> 12.794029 | AA23: =(J23-$Q$4)/$Q$3 -> 0.42380214 | AB23: =(K23-$N$19)/$N$18 -> 0.026849543 | AD23: 21 | AE23: Without B3 72h | AF23: =(U23*0.0005*1000) /$AU$21 -> 0.26410026 | AG23: =(V23*0.0005*1000) /$AU23 -> 0.29802066 | AH23: =(W23*0.0005*1000) /$AU23 -> 0.87273775 | AI23: =(X23*0.0005*1000) /$AU23 -> 3.7004987 | AJ23: =(Y23*0.0005*1000) /$AU23 -> 3.4838869 | AK23: =(Z23*0.0005*1000) /$AU23 -> 51.026207 | AL23: =(AA23*0.0005*1000) /$AU23 -> 1.6902428 | AM23: =(AB23*0.0005*1000) /$AU23 -> 0.10708357 | AP23: 21 | AQ23: 0.38936668 | AR23: 0.25666668 | AS23: 0.40689268 | AT23: 0.1220678 | AU23: 0.12536723 | AW23: 21 | AX23: Without B3 72h | AY23: 45194861 | AZ23: 296319.07 | BA23: 126519.68 | BC23: Without B3 72h | BD23: =AY23/$AT23 -> 3.7024391e+08 | BE23: =AZ23/$AT23 -> 2427495.7 | BF23: =BA23/$AT23 -> 1036470.5
A24: 22 | B24: Without B5 72h | C24: 99033.798 | D24: 160876.7 | E24: 1793605.6 | F24: 16486025 | G24: 4928.0404 | H24: 3822466.8 | I24: 20892105 | J24: 5978117.5 | K24: 181100.44 | N24: n = c * V | S24: 22 | T24: Without B5 72h | U24: =(C24-$N$4)/$N$3 -> 0.065179709 | V24: =(D24-$O$12)/$O$11 -> 0.072645896 | W24: =(F24-$O$4)/$O$3 -> 1.3821744 | X24: =(G24-$O$8)/$O$7 -> 0.92750978 | Y24: =(H24-$P$8)/$P$7 -> 0.87261915 | Z24: =(I24-$P$4)/$P$3 -> 10.931145 | AA24: =(J24-$Q$4)/$Q$3 -> 0.39922087 | AB24: =(K24-$N$19)/$N$18 -> 0.40175353 | AD24: 22 | AE24: Without B5 72h | AF24: =(U24*0.0005*1000) /$AU$24 -> 0.26414828 | AG24: =(V24*0.0005*1000) /$AU24 -> 0.29440586 | AH24: =(W24*0.0005*1000) /$AU24 -> 5.6014209 | AI24: =(X24*0.0005*1000) /$AU24 -> 3.7588402 | AJ24: =(Y24*0.0005*1000) /$AU24 -> 3.5363896 | AK24: =(Z24*0.0005*1000) /$AU24 -> 44.299725 | AL24: =(AA24*0.0005*1000) /$AU24 -> 1.6178886 | AM24: =(AB24*0.0005*1000) /$AU24 -> 1.6281525 | AP24: 22 | AQ24: 0.40373333 | AR24: 0.27103334 | AS24: 0.43124294 | AT24: 0.12937288 | AU24: 0.12337712 | AW24: 22 | AX24: Without B5 72h | AY24: 28089550 | AZ24: 11150320 | BA24: 1507239.9 | BC24: Without B5 72h | BD24: =AY24/$AT24 -> 2.1712085e+08 | BE24: =AZ24/$AT24 -> 86187456 | BF24: =BA24/$AT24 -> 11650354
A25: 23 | B25: Without B5 72h | C25: 98147.103 | D25: 160192.15 | E25: 1392471.1 | F25: 16401016 | G25: 13347.359 | H25: 3221538.8 | I25: 18524314 | J25: 4893850.1 | K25: 162739.2 | S25: 23 | T25: Without B5 72h | U25: =(C25-$N$4)/$N$3 -> 0.065099762 | V25: =(D25-$O$12)/$O$11 -> 0.072575895 | W25: =(F25-$O$4)/$O$3 -> 1.3751574 | X25: =(G25-$O$8)/$O$7 -> 0.93916102 | Y25: =(H25-$P$8)/$P$7 -> 0.75327719 | Z25: =(I25-$P$4)/$P$3 -> 9.6992491 | AA25: =(J25-$Q$4)/$Q$3 -> 0.34325825 | AB25: =(K25-$N$19)/$N$18 -> 0.35840585 | AD25: 23 | AE25: Without B5 72h | AF25: =(U25*0.0005*1000) /$AU$24 -> 0.26382429 | AG25: =(V25*0.0005*1000) /$AU25 -> 0.29412218 | AH25: =(W25*0.0005*1000) /$AU25 -> 5.5729839 | AI25: =(X25*0.0005*1000) /$AU25 -> 3.8060582 | AJ25: =(Y25*0.0005*1000) /$AU25 -> 3.0527426 | AK25: =(Z25*0.0005*1000) /$AU25 -> 39.307325 | AL25: =(AA25*0.0005*1000) /$AU25 -> 1.3910936 | AM25: =(AB25*0.0005*1000) /$AU25 -> 1.452481 | AP25: 23 | AQ25: 0.32826667 | AR25: 0.19556667 | AS25: 0.30333335 | AT25: 0.091000004 | AU25: 0.12337712 | AW25: 23 | AX25: Without B5 72h | AY25: 25434520 | AZ25: 6749522.6 | BA25: 856278.62 | BC25: Without B5 72h | BD25: =AY25/$AT25 -> 2.7950021e+08 | BE25: =AZ25/$AT25 -> 74170575 | BF25: =BA25/$AT25 -> 9409654.8
A26: 24 | B26: Without B5 72h | C26: 89217.496 | D26: 157595.52 | E26: 1400621.4 | F26: 15628126 | G26: 4185.565 | H26: 3027652.9 | I26: 19379937 | J26: 4837840.5 | K26: 147759.98 | N26: c = n/V | S26: 24 | T26: Without B5 72h | U26: =(C26-$N$4)/$N$3 -> 0.06429465 | V26: =(D26-$O$12)/$O$11 -> 0.072310369 | W26: =(F26-$O$4)/$O$3 -> 1.3113601 | X26: =(G26-$O$8)/$O$7 -> 0.92648229 | Y26: =(H26-$P$8)/$P$7 -> 0.71477221 | Z26: =(I26-$P$4)/$P$3 -> 10.144406 | AA26: =(J26-$Q$4)/$Q$3 -> 0.34036742 | AB26: =(K26-$N$19)/$N$18 -> 0.32304251 | AD26: 24 | AE26: Without B5 72h | AF26: =(U26*0.0005*1000) /$AU$24 -> 0.26056148 | AG26: =(V26*0.0005*1000) /$AU26 -> 0.2930461 | AH26: =(W26*0.0005*1000) /$AU26 -> 5.314438 | AI26: =(X26*0.0005*1000) /$AU26 -> 3.7546762 | AJ26: =(Y26*0.0005*1000) /$AU26 -> 2.8966967 | AK26: =(Z26*0.0005*1000) /$AU26 -> 41.111376 | AL26: =(AA26*0.0005*1000) /$AU26 -> 1.3793782 | AM26: =(AB26*0.0005*1000) /$AU26 -> 1.309167 | AP26: 24 | AQ26: 0.38015001 | AR26: 0.24745001 | AS26: 0.3912712 | AT26: 0.11738136 | AU26: 0.12337712 | AW26: 24 | AX26: Without B5 72h | AY26: 25814753 | AZ26: 19574207 | BA26: 997443.33 | BC26: Without B5 72h | BD26: =AY26/$AT26 -> 2.1992208e+08 | BE26: =AZ26/$AT26 -> 1.6675737e+08 | BF26: =BA26/$AT26 -> 8497459.3
A27: C1 | B27: Fully supplemented 24h (concentrated) | C27: 222909.9 | D27: 266725.04 | E27: 7426321.6 | F27: 28422472 | G27: 102727.61 | H27: 15489628 | I27: 18877417 | J27: 7552653.3 | K27: 516245.9 | S27: C1 | T27: Fully supplemented 24h (concentrated) | U27: =(C27-$N$4)/$N$3 -> 0.076348638 | V27: =(D27-$O$12)/$O$11 -> 0.083469763 | W27: =(F27-$O$4)/$O$3 -> 2.3674549 | X27: =((G27-$O$8)/$O$7) / 6 -> 0.17714195 | Y27: =(H27-$P$8)/$P$7 -> 3.189672 | Z27: =(I27-$P$4)/$P$3 -> 9.8829588 | AA27: =((J27-$Q$4)/$Q$3)/6 -> 0.080081308 | AB27: =(K27-$N$19)/$N$18 -> 1.1929738 | AD27: C1 | AE27: Fully supplemented 24h (concentrated) | AF27: =((U27 * 0.00005 * 1000) * (0.0005/0.0003) )/$AU$3 -> 0.072306808 | AG27: =(V27*0.0005*1000) /$AU3 -> 0.47430569 | AH27: =(W27*0.0005*1000) /$AU3 -> 13.452744 | AI27: =(X27*0.0005*1000) /$AU3 -> 1.0065853 | AJ27: =(Y27*0.0005*1000) /$AU3 -> 18.124882 | AK27: =(Z27*0.0005*1000) /$AU3 -> 56.158582 | AL27: =(AA27*0.0005*1000) /$AU3 -> 0.45505125 | AM27: =(AB27*0.0005*1000) /$AU3 -> 6.7789132 | AP27: M1 | AQ27: 0.32718273 | AR27: 0.21741759 | AS27: 0.35354323 | AT27: 1.0606297 | AW27: C1 | AX27: Fully supplemented 24h (concentrated) | AY27: 26798996 | AZ27: 1567495.7 | BA27: 91421.533 | BC27: Fully supplemented 24h (concentrated) | BD27: =AY27/$AT3 -> 2.3962124e+08 | BE27: =AZ27/$AT3 -> 14015647 | BF27: =BA27/$AT3 -> 817438.87
A28: C2 | B28: Fully supplemented 24h (concentrated) | C28: 128209.24 | D28: 250202.02 | E28: 5100530.8 | F28: 16286779 | G28: 0 | H28: 8585909.6 | I28: 11463991 | J28: 5298947.5 | K28: 329480.03 | S28: C2 | T28: Fully supplemented 24h (concentrated) | U28: =((C28-$N$4)/$N$3)/6 -> 0.011301705 | V28: =(D28-$O$12)/$O$11 -> 0.081780148 | W28: =(F28-$O$4)/$O$3 -> 1.3657279 | X28: =((G28-$O$8)/$O$7) / 6 -> 0.15344833 | Y28: =(H28-$P$8)/$P$7 -> 1.8186203 | Z28: =(I28-$P$4)/$P$3 -> 6.0259591 | AA28: =(J28-$Q$4)/$Q$3 -> 0.36416666 | AB28: =(K28-$N$19)/$N$18 -> 0.752052 | AD28: C2 | AE28: Fully supplemented 24h (concentrated) | AF28: =((U28 * 0.00005 * 1000) * (0.0005/0.0003) )/$AU$3 -> 0.010703402 | AG28: =(V28*0.0005*1000) /$AU4 -> 0.46470468 | AH28: =(W28*0.0005*1000) /$AU4 -> 7.7605648 | AI28: =(X28*0.0005*1000) /$AU4 -> 0.8719495 | AJ28: =(Y28*0.0005*1000) /$AU4 -> 10.334065 | AK28: =(Z28*0.0005*1000) /$AU4 -> 34.241701 | AL28: =(AA28*0.0005*1000) /$AU4 -> 2.069328 | AM28: =(AB28*0.0005*1000) /$AU4 -> 4.2734342 | AP28: M2 | AQ28: 0.35002199 | AR28: 0.24025685 | AS28: 0.39385254 | AT28: 1.1815576 | AW28: C2 | AX28: Fully supplemented 24h (concentrated) | AY28: 14453838 | AZ28: 1906021.4 | BA28: 40502.229 | BC28: Fully supplemented 24h (concentrated) | BD28: =AY28/$AT4 -> 1.7960751e+08 | BE28: =AZ28/$AT4 -> 23684764 | BF28: =BA28/$AT4 -> 503292.23
A29: C3 | B29: Fully supplemented 24h (concentrated) | C29: 197918.27 | D29: 409321.98 | E29: 17840931 | F29: 22312226 | G29: 0 | H29: 15802475 | I29: 11056347 | J29: 7074180.3 | K29: 442414.07 | S29: C3 | T29: Fully supplemented 24h (concentrated) | U29: =((C29-$N$4)/$N$3)/6 -> 0.012349223 | V29: =(D29-$O$12)/$O$11 -> 0.098051479 | W29: =(F29-$O$4)/$O$3 -> 1.8630916 | X29: =((G29-$O$8)/$O$7) / 6 -> 0.15344833 | Y29: =(H29-$P$8)/$P$7 -> 3.2518022 | Z29: =(I29-$P$4)/$P$3 -> 5.8138732 | AA29: =(J29-$Q$4)/$Q$3 -> 0.45579228 | AB29: =(K29-$N$19)/$N$18 -> 1.0186697 | AD29: C3 | AE29: Fully supplemented 24h (concentrated) | AF29: =((U29 * 0.00005 * 1000) * (0.0005/0.0003) )/$AU$3 -> 0.011695466 | AG29: =(V29*0.0005*1000) /$AU5 -> 0.55716432 | AH29: =(W29*0.0005*1000) /$AU5 -> 10.586767 | AI29: =(X29*0.0005*1000) /$AU5 -> 0.8719495 | AJ29: =(Y29*0.0005*1000) /$AU5 -> 18.477928 | AK29: =(Z29*0.0005*1000) /$AU5 -> 33.036551 | AL29: =(AA29*0.0005*1000) /$AU5 -> 2.5899782 | AM29: =(AB29*0.0005*1000) /$AU5 -> 5.7884533 | AP29: M3 | AQ29: 0.3375262 | AR29: 0.22776107 | AS29: 0.37179857 | AT29: 1.1153957 | AW29: C3 | AX29: Fully supplemented 24h (concentrated) | AY29: 21981927 | AZ29: 3123331.5 | BA29: 597937.65 | BC29: Fully supplemented 24h (concentrated) | BD29: =AY29/$AT5 -> 3.0674873e+08 | BE29: =AZ29/$AT5 -> 43584805 | BF29: =BA29/$AT5 -> 8343973.5
A30: C4 | B30: w/o B2, B3, B5 24h (concentrated) | C30: 172847.6 | D30: 397766.11 | E30: 61777647 | F30: 13538905 | G30: 112620.27 | H30: 22680302 | I30: 12753537 | J30: 7833380.9 | K30: 249030.4 | S30: C4 | T30: w/o B2, B3, B5 24h (concentrated) | U30: =((C30-$N$4)/$N$3)/6 -> 0.011972486 | V30: =(D30-$O$12)/$O$11 -> 0.096869795 | W30: =(F30-$O$4)/$O$3 -> 1.1389077 | X30: =((G30-$O$8)/$O$7) / 6 -> 0.17942365 | Y30: =(H30-$P$8)/$P$7 -> 4.6177117 | Z30: =(I30-$P$4)/$P$3 -> 6.6968745 | AA30: =(J30-$Q$4)/$Q$3 -> 0.49497712 | AB30: =(K30-$N$19)/$N$18 -> 0.56212439 | AD30: C4 | AE30: w/o B2, B3, B5 24h (concentrated) | AF30: =((U30 * 0.00005 * 1000) * (0.0005/0.0003) )/$AU$6 -> 0.011655226 | AG30: =(V30*0.0005*1000) /$AU6 -> 0.56581703 | AH30: =(W30*0.0005*1000) /$AU6 -> 6.6523664 | AI30: =(X30*0.0005*1000) /$AU6 -> 1.0480145 | AJ30: =(Y30*0.0005*1000) /$AU6 -> 26.972081 | AK30: =(Z30*0.0005*1000) /$AU6 -> 39.116482 | AL30: =(AA30*0.0005*1000) /$AU6 -> 2.8911642 | AM30: =(AB30*0.0005*1000) /$AU6 -> 3.2833718 | AP30: M4 | AQ30: 0.33962814 | AR30: 0.22986301 | AS30: 0.3755083 | AT30: 1.1265249 | AW30: C4 | AX30: w/o B2, B3, B5 24h (concentrated) | AY30: 3355962 | AZ30: 832009.76 | BA30: 0 | BC30: w/o B2, B3, B5 24h (concentrated) | BD30: =AY30/$AT6 -> 38808655 | BE30: =AZ30/$AT6 -> 9621437.8 | BF30: =BA30/$AT6 -> 0
A31: C5 | B31: w/o B2, B3, B5 24h (concentrated) | C31: 155192.4 | D31: 513104.6 | E31: 63642184 | F31: 12389755 | G31: 0 | H31: 21799350 | I31: 10391064 | J31: 9328565.5 | K31: 225270.47 | S31: C5 | T31: w/o B2, B3, B5 24h (concentrated) | U31: =((C31-$N$4)/$N$3)/6 -> 0.011707181 | V31: =(D31-$O$12)/$O$11 -> 0.10866411 | W31: =(F31-$O$4)/$O$3 -> 1.0440524 | X31: =((G31-$O$8)/$O$7) / 6 -> 0.15344833 | Y31: =(H31-$P$8)/$P$7 -> 4.4427581 | Z31: =(I31-$P$4)/$P$3 -> 5.467745 | AA31: =(J31-$Q$4)/$Q$3 -> 0.57214852 | AB31: =(K31-$N$19)/$N$18 -> 0.50603133 | AD31: C5 | AE31: w/o B2, B3, B5 24h (concentrated) | AF31: =((U31 * 0.00005 * 1000) * (0.0005/0.0003) )/$AU$6 -> 0.011396952 | AG31: =(V31*0.0005*1000) /$AU7 -> 0.63470768 | AH31: =(W31*0.0005*1000) /$AU7 -> 6.0983162 | AI31: =(X31*0.0005*1000) /$AU7 -> 0.8962926 | AJ31: =(Y31*0.0005*1000) /$AU7 -> 25.950176 | AK31: =(Z31*0.0005*1000) /$AU7 -> 31.93713 | AL31: =(AA31*0.0005*1000) /$AU7 -> 3.3419228 | AM31: =(AB31*0.0005*1000) /$AU7 -> 2.9557319 | AP31: M5 | AQ31: 0.33765118 | AR31: 0.22788605 | AS31: 0.37201915 | AT31: 1.1160574 | AW31: C5 | AX31: w/o B2, B3, B5 24h (concentrated) | AY31: 3048769.4 | AZ31: 853179.78 | BA31: 0 | BC31: w/o B2, B3, B5 24h (concentrated) | BD31: =AY31/$AT7 -> 35982674 | BE31: =AZ31/$AT7 -> 10069535 | BF31: =BA31/$AT7 -> 0
A32: C6 | B32: w/o B2, B3, B5 24h (concentrated) | C32: 173544.12 | D32: 459266.88 | E32: 84842239 | F32: 12285354 | G32: 0 | H32: 23041411 | I32: 8900640.8 | J32: 9316103.5 | K32: 217001.82 | S32: C6 | T32: w/o B2, B3, B5 24h (concentrated) | U32: =((C32-$N$4)/$N$3)/6 -> 0.011982953 | V32: =(D32-$O$12)/$O$11 -> 0.10315876 | W32: =(F32-$O$4)/$O$3 -> 1.0354347 | X32: =((G32-$O$8)/$O$7) / 6 -> 0.15344833 | Y32: =(H32-$P$8)/$P$7 -> 4.6894267 | Z32: =(I32-$P$4)/$P$3 -> 4.6923193 | AA32: =(J32-$Q$4)/$Q$3 -> 0.57150532 | AB32: =(K32-$N$19)/$N$18 -> 0.48651047 | AD32: C6 | AE32: w/o B2, B3, B5 24h (concentrated) | AF32: =((U32 * 0.00005 * 1000) * (0.0005/0.0003) )/$AU$6 -> 0.011665416 | AG32: =(V32*0.0005*1000) /$AU8 -> 0.60255089 | AH32: =(W32*0.0005*1000) /$AU8 -> 6.0479802 | AI32: =(X32*0.0005*1000) /$AU8 -> 0.8962926 | AJ32: =(Y32*0.0005*1000) /$AU8 -> 27.390968 | AK32: =(Z32*0.0005*1000) /$AU8 -> 27.407864 | AL32: =(AA32*0.0005*1000) /$AU8 -> 3.3381658 | AM32: =(AB32*0.0005*1000) /$AU8 -> 2.8417104 | AP32: M6 | AQ32: 0.31639637 | AR32: 0.20663124 | AS32: 0.33450624 | AT32: 1.0035187 | AW32: C6 | AX32: w/o B2, B3, B5 24h (concentrated) | AY32: 2995179.8 | AZ32: 1326156.8 | BA32: 0 | BC32: w/o B2, B3, B5 24h (concentrated) | BD32: =AY32/$AT8 -> 88357805 | BE32: =AZ32/$AT8 -> 39121627 | BF32: =BA32/$AT8 -> 0
A33: C7 | B33: Without B3 24h (concentrated) | C33: 237883.73 | D33: 424097.77 | E33: 2448980.8 | F33: 15542370 | G33: 139065.85 | H33: 10077501 | I33: 24237687 | J33: 13019965 | K33: 252233.43 | S33: C7 | T33: Without B3 24h (concentrated) | U33: =((C33-$N$4)/$N$3)/6 -> 0.012949785 | V33: =(D33-$O$12)/$O$11 -> 0.099562425 | W33: =(F33-$O$4)/$O$3 -> 1.3042815 | X33: =((G33-$O$8)/$O$7) / 6 -> 0.18552319 | Y33: =(H33-$P$8)/$P$7 -> 2.1148447 | Z33: =(I33-$P$4)/$P$3 -> 12.671759 | AA33: =(J33-$Q$4)/$Q$3 -> 0.76267381 | AB33: =(K33-$N$19)/$N$18 -> 0.56968621 | AD33: C7 | AE33: Without B3 24h (concentrated) | AF33: =((U33 * 0.00005 * 1000) * (0.0005/0.0003) )/$AU$9 -> 0.01950966 | AG33: =(V33*0.0005*1000) /$AU9 -> 0.89998208 | AH33: =(W33*0.0005*1000) /$AU9 -> 11.789889 | AI33: =(X33*0.0005*1000) /$AU9 -> 1.6770136 | AJ33: =(Y33*0.0005*1000) /$AU9 -> 19.116874 | AK33: =(Z33*0.0005*1000) /$AU9 -> 114.54478 | AL33: =(AA33*0.0005*1000) /$AU9 -> 6.8940944 | AM33: =(AB33*0.0005*1000) /$AU9 -> 5.1496071 | AP33: M7 | AQ33: 0.37143027 | AR33: 0.26166514 | AS33: 0.43163631 | AT33: 1.2949089 | AW33: C7 | AX33: Without B3 24h (concentrated) | AY33: 40437041 | AZ33: 935333.22 | BA33: 265458.89 | BC33: Without B3 24h (concentrated) | BD33: =AY33/$AT9 -> 6.6997624e+08 | BE33: =AZ33/$AT9 -> 15496956 | BF33: =BA33/$AT9 -> 4398223.7
A34: C8 | B34: Without B3 24h (concentrated) | C34: 263550.4 | D34: 476533.52 | E34: 3504328.3 | F34: 18354292 | G34: 104519.4 | H34: 11121090 | I34: 27150366 | J34: 12319929 | K34: 269918.72 | S34: C8 | T34: Without B3 24h (concentrated) | U34: =((C34-$N$4)/$N$3)/6 -> 0.013335478 | V34: =(D34-$O$12)/$O$11 -> 0.10492441 | W34: =(F34-$O$4)/$O$3 -> 1.5363884 | X34: =((G34-$O$8)/$O$7) / 6 -> 0.17755522 | Y34: =(H34-$P$8)/$P$7 -> 2.3220973 | Z34: =(I34-$P$4)/$P$3 -> 14.187145 | AA34: =(J34-$Q$4)/$Q$3 -> 0.72654263 | AB34: =(K34-$N$19)/$N$18 -> 0.6114381 | AD34: C8 | AE34: Without B3 24h (concentrated) | AF34: =((U34 * 0.00005 * 1000) * (0.0005/0.0003) )/$AU$9 -> 0.020090731 | AG34: =(V34*0.0005*1000) /$AU10 -> 0.9484511 | AH34: =(W34*0.0005*1000) /$AU10 -> 13.88799 | AI34: =(X34*0.0005*1000) /$AU10 -> 1.6049882 | AJ34: =(Y34*0.0005*1000) /$AU10 -> 20.990308 | AK34: =(Z34*0.0005*1000) /$AU10 -> 128.24292 | AL34: =(AA34*0.0005*1000) /$AU10 -> 6.5674911 | AM34: =(AB34*0.0005*1000) /$AU10 -> 5.5270181 | AP34: M8 | AQ34: 0.35071026 | AR34: 0.24094512 | AS34: 0.39506728 | AT34: 1.1852018 | AW34: C8 | AX34: Without B3 24h (concentrated) | AY34: 53171501 | AZ34: 1062994.4 | BA34: 249768.6 | BC34: Without B3 24h (concentrated) | BD34: =AY34/$AT10 -> 4.8690337e+08 | BE34: =AZ34/$AT10 -> 9734078 | BF34: =BA34/$AT10 -> 2287187.1
A35: C9 | B35: Without B3 24h (concentrated) | C35: 264745.3 | D35: 442431.32 | E35: 3879184.9 | F35: 16991296 | G35: 106943.78 | H35: 11156039 | I35: 32359111 | J35: 12286211 | K35: 265756.47 | S35: C9 | T35: Without B3 24h (concentrated) | U35: =((C35-$N$4)/$N$3)/6 -> 0.013353434 | V35: =(D35-$O$12)/$O$11 -> 0.10143718 | W35: =(F35-$O$4)/$O$3 -> 1.4238814 | X35: =((G35-$O$8)/$O$7) / 6 -> 0.17811439 | Y35: =(H35-$P$8)/$P$7 -> 2.329038 | Z35: =(I35-$P$4)/$P$3 -> 16.89711 | AA35: =(J35-$Q$4)/$Q$3 -> 0.72480233 | AB35: =(K35-$N$19)/$N$18 -> 0.60161174 | AD35: C9 | AE35: Without B3 24h (concentrated) | AF35: =((U35 * 0.00005 * 1000) * (0.0005/0.0003) )/$AU$9 -> 0.020117783 | AG35: =(V35*0.0005*1000) /$AU11 -> 0.9169287 | AH35: =(W35*0.0005*1000) /$AU11 -> 12.870998 | AI35: =(X35*0.0005*1000) /$AU11 -> 1.6100427 | AJ35: =(Y35*0.0005*1000) /$AU11 -> 21.053047 | AK35: =(Z35*0.0005*1000) /$AU11 -> 152.73931 | AL35: =(AA35*0.0005*1000) /$AU11 -> 6.5517599 | AM35: =(AB35*0.0005*1000) /$AU11 -> 5.438194 | AP35: M9 | AQ35: 0.34742543 | AR35: 0.2376603 | AS35: 0.38926985 | AT35: 1.1678095 | AW35: C9 | AX35: Without B3 24h (concentrated) | AY35: 43974790 | AZ35: 808491.29 | BA35: 287896.36 | BC35: Without B3 24h (concentrated) | BD35: =AY35/$AT11 -> 8.7475137e+08 | BE35: =AZ35/$AT11 -> 16082598 | BF35: =BA35/$AT11 -> 5726866.2
A36: C10 | B36: Without B5 24h (concentrated) | C36: 188514.33 | D36: 325913.53 | E36: 2373773.8 | F36: 27669512 | G36: 0 | H36: 8756636.9 | I36: 20686990 | J36: 10168880 | K36: 372676.52 | O36: =0.076/6 -> 0.012666667 | P36: =0.076*6 -> 0.456 | S36: C10 | T36: Without B5 24h (concentrated) | U36: =((C36-$N$4)/$N$3)/6 -> 0.01220791 | V36: =(D36-$O$12)/$O$11 -> 0.089522276 | W36: =(F36-$O$4)/$O$3 -> 2.3053027 | X36: =((G36-$O$8)/$O$7) / 6 -> 0.15344833 | Y36: =(H36-$P$8)/$P$7 -> 1.8525261 | Z36: =(I36-$P$4)/$P$3 -> 10.82443 | AA36: =(J36-$Q$4)/$Q$3 -> 0.61551991 | AB36: =(K36-$N$19)/$N$18 -> 0.85403142 | AD36: C10 | AE36: Without B5 24h (concentrated) | AF36: =((U36 * 0.00005 * 1000) * (0.0005/0.0003) )/$AU$12 -> 0.0098405153 | AG36: =(V36*0.0005*1000) /$AU12 -> 0.43297108 | AH36: =(W36*0.0005*1000) /$AU12 -> 11.149509 | AI36: =(X36*0.0005*1000) /$AU12 -> 0.74214702 | AJ36: =(Y36*0.0005*1000) /$AU12 -> 8.9596719 | AK36: =(Z36*0.0005*1000) /$AU12 -> 52.351942 | AL36: =(AA36*0.0005*1000) /$AU12 -> 2.9769386 | AM36: =(AB36*0.0005*1000) /$AU12 -> 4.1304904 | AP36: M10 | AQ36: 0.32684358 | AR36: 0.21707845 | AS36: 0.35294467 | AT36: 1.058834 | AW36: C10 | AX36: Without B5 24h (concentrated) | AY36: 0 | AZ36: 10339280 | BA36: 3841475.2 | BC36: Without B5 24h (concentrated) | BD36: =AY36/$AT12 -> 0 | BE36: =AZ36/$AT12 -> 2.7702883e+08 | BF36: =BA36/$AT12 -> 1.0292781e+08
A37: C11 | B37: Without B5 24h (concentrated) | C37: 224781.08 | D37: 410224.79 | E37: 2446283.1 | F37: 31200023 | G37: 0 | H37: 9491844.7 | I37: 24547435 | J37: 10945034 | K37: 415347.05 | S37: C11 | T37: Without B5 24h (concentrated) | U37: =((C37-$N$4)/$N$3)/6 -> 0.012752891 | V37: =(D37-$O$12)/$O$11 -> 0.098143799 | W37: =(F37-$O$4)/$O$3 -> 2.5967248 | X37: =((G37-$O$8)/$O$7) / 6 -> 0.15344833 | Y37: =(H37-$P$8)/$P$7 -> 1.9985355 | Z37: =(I37-$P$4)/$P$3 -> 12.832912 | AA37: =(J37-$Q$4)/$Q$3 -> 0.65557979 | AB37: =(K37-$N$19)/$N$18 -> 0.95476915 | AD37: C11 | AE37: Without B5 24h (concentrated) | AF37: =((U37 * 0.00005 * 1000) * (0.0005/0.0003) )/$AU$12 -> 0.010279812 | AG37: =(V37*0.0005*1000) /$AU13 -> 0.47466874 | AH37: =(W37*0.0005*1000) /$AU13 -> 12.55896 | AI37: =(X37*0.0005*1000) /$AU13 -> 0.74214702 | AJ37: =(Y37*0.0005*1000) /$AU13 -> 9.6658409 | AK37: =(Z37*0.0005*1000) /$AU13 -> 62.065891 | AL37: =(AA37*0.0005*1000) /$AU13 -> 3.1706867 | AM37: =(AB37*0.0005*1000) /$AU13 -> 4.6177046 | AP37: M11 | AQ37: 0.35282372 | AR37: 0.24305858 | AS37: 0.39879736 | AT37: 1.1963921 | AW37: C11 | AX37: Without B5 24h (concentrated) | AY37: 30013361 | AZ37: 4441669.6 | BA37: 3612506.1 | BC37: Without B5 24h (concentrated) | BD37: =AY37/$AT13 -> 3.002863e+08 | BE37: =AZ37/$AT13 -> 44439293 | BF37: =BA37/$AT13 -> 36143440
A38: C12 | B38: Without B5 24h (concentrated) | C38: 232232.56 | D38: 460217.13 | E38: 2925030.5 | F38: 33517004 | G38: 0 | H38: 8838713.6 | I38: 22355549 | J38: 11270700 | K38: 464124.44 | O38: =O36*6 -> 0.076 | P38: =0.456/6 -> 0.076 | S38: C12 | T38: Without B5 24h (concentrated) | U38: =((C38-$N$4)/$N$3)/6 -> 0.012864865 | V38: =(D38-$O$12)/$O$11 -> 0.10325593 | W38: =(F38-$O$4)/$O$3 -> 2.7879773 | X38: =((G38-$O$8)/$O$7) / 6 -> 0.15344833 | Y38: =(H38-$P$8)/$P$7 -> 1.8688262 | Z38: =(I38-$P$4)/$P$3 -> 11.692534 | AA38: =(J38-$Q$4)/$Q$3 -> 0.67238847 | AB38: =(K38-$N$19)/$N$18 -> 1.0699241 | AD38: C12 | AE38: Without B5 24h (concentrated) | AF38: =((U38 * 0.00005 * 1000) * (0.0005/0.0003) )/$AU$12 -> 0.010370071 | AG38: =(V38*0.0005*1000) /$AU14 -> 0.49939336 | AH38: =(W38*0.0005*1000) /$AU14 -> 13.483946 | AI38: =(X38*0.0005*1000) /$AU14 -> 0.74214702 | AJ38: =(Y38*0.0005*1000) /$AU14 -> 9.0385068 | AK38: =(Z38*0.0005*1000) /$AU14 -> 56.550497 | AL38: =(AA38*0.0005*1000) /$AU14 -> 3.2519812 | AM38: =(AB38*0.0005*1000) /$AU14 -> 5.1746472 | AP38: M12 | AQ38: 0.33371183 | AR38: 0.22394669 | AS38: 0.36506653 | AT38: 1.0951996 | AW38: C12 | AX38: Without B5 24h (concentrated) | AY38: 39778672 | AZ38: 8757185.7 | BA38: 6385572.7 | BC38: Without B5 24h (concentrated) | BD38: =AY38/$AT14 -> 3.7241217e+08 | BE38: =AZ38/$AT14 -> 81985707 | BF38: =BA38/$AT14 -> 59782413
